#VRML_SIM R2022a utf8
WorldInfo {
}
Viewpoint {
  orientation -0.3606179157362538 -0.29810726072406823 0.883791140458894 4.493303112516124
  position 0.0838419610985558 4.82613738632856 6.033947693742791
}
TexturedBackground {
}
TexturedBackgroundLight {
}
RectangleArena {
  floorSize 25 10
}
Robot {
  translation -9 0 0
  children [
    Solid {
      children [
        HingeJoint {
          jointParameters HingeJointParameters {
            axis 0 0 1
          }
          device [
            RotationalMotor {
              name "Base_motor"
            }
          ]
          endPoint Solid {
            translation 0 0 0.09999999999999892
            children [
              Solid {
                rotation 0 0 1 4.692820414042842e-06
                children [
                  DEF Base Shape {
                    appearance PBRAppearance {
                    }
                    geometry Cylinder {
                      height 0.1
                      radius 0.2
                    }
                  }
                  Solid {
                    translation 0 0 0.3
                    rotation 0 1 0 0
                    children [
                      HingeJoint {
                        jointParameters HingeJointParameters {
                          axis 0 1 0
                          anchor 0 0 0.35
                        }
                        device [
                          RotationalMotor {
                            name "Shoulder_motor"
                            maxTorque 100
                          }
                        ]
                        endPoint Solid {
                          translation 0 0 0.35
                          rotation 1 9.813077866797664e-18 -9.813077866797664e-18 1.570796326789991
                          children [
                            DEF shoulder Shape {
                              appearance PBRAppearance {
                                baseColor 1 0 0
                                roughness 1
                              }
                              geometry Cylinder {
                                height 0.1
                                radius 0.05
                              }
                            }
                            Solid {
                              translation -0.2 0 0.1
                              rotation 0 1 0 -1.5708
                              children [
                                DEF L2 Shape {
                                  appearance PBRAppearance {
                                    baseColor 1 0 1
                                    roughness 1
                                  }
                                  geometry Cylinder {
                                    height 0.5
                                    radius 0.05
                                  }
                                }
                                HingeJoint {
                                  jointParameters HingeJointParameters {
                                    anchor 0 0 0.3
                                    springConstant 1
                                    dampingConstant 1
                                  }
                                  device [
                                    RotationalMotor {
                                      name "Elbow_motor"
                                      maxTorque 100
                                    }
                                  ]
                                  endPoint Solid {
                                    translation 0 4.750001949524506e-20 0.300234
                                    rotation -3.64161980102732e-19 -1 -2.491634600702903e-19 1.5707699999999944
                                    children [
                                      Solid {
                                        translation 0.15 0 0.1
                                        rotation 0 1 0 1.57079632679
                                        children [
                                          GPS {
                                            translation 0 0 0.2
                                          }
                                          DEF L3 Shape {
                                            appearance PBRAppearance {
                                            }
                                            geometry Cylinder {
                                              height 0.4
                                              radius 0.05
                                            }
                                          }
                                        ]
                                        boundingObject USE L3
                                        physics Physics {
                                        }
                                      }
                                      DEF elbow Shape {
                                        appearance PBRAppearance {
                                          baseColor 1 0.6 0
                                          roughness 1
                                        }
                                        geometry Cylinder {
                                          height 0.1
                                          radius 0.05
                                        }
                                      }
                                    ]
                                    boundingObject USE elbow
                                    physics Physics {
                                    }
                                  }
                                }
                              ]
                              boundingObject USE L2
                              physics Physics {
                              }
                            }
                          ]
                          boundingObject USE shoulder
                          physics Physics {
                          }
                        }
                      }
                      DEF L1 Shape {
                        appearance PBRAppearance {
                        }
                        geometry Cylinder {
                          height 0.6
                          radius 0.05
                        }
                      }
                    ]
                    boundingObject USE L1
                    physics Physics {
                    }
                  }
                ]
                boundingObject USE Base
                physics Physics {
                }
              }
            ]
            boundingObject DEF Base Shape {
              appearance PBRAppearance {
              }
              geometry Cylinder {
                height 0.1
                radius 0.2
              }
            }
            physics Physics {
            }
          }
        }
        DEF Platform Shape {
          appearance PBRAppearance {
            baseColor 0 1 1
          }
          geometry Cylinder {
            height 0.1
          }
        }
      ]
      boundingObject USE Platform
      physics Physics {
      }
    }
  ]
  controller ""
}
Robot {
  translation 8 0 1.3
  rotation 0 1 0 0
  children [
    Solid {
      rotation 1 0 0 1.57079632679
      children [
        UR10BaseShape {
        }
        Transform {
          translation 0 0.1273 0
          children [
            HingeJoint {
              jointParameters HingeJointParameters {
                axis 0 1 0
              }
              device [
                RotationalMotor {
                  name "shoulder_pan_joint"
                  maxVelocity 2.16
                  minPosition -3.14159265359
                  maxPosition 3.14159265359
                  maxTorque 330
                }
              ]
              endPoint Solid {
                rotation 0 1 0 0
                children [
                  UR10ShoulderShape {
                  }
                  Transform {
                    translation 0 0 0.220941
                    rotation 0 0 1 1.57079632679
                    children [
                      HingeJoint {
                        jointParameters HingeJointParameters {
                          axis 0 0 1
                        }
                        device [
                          RotationalMotor {
                            name "shoulder_lift_joint"
                            maxVelocity 2.16
                            minPosition -3.14159265359
                            maxPosition 3.14159265359
                            maxTorque 330
                          }
                        ]
                        endPoint Solid {
                          children [
                            UR10UpperArmShape {
                            }
                            Transform {
                              translation 0 0.612 -0.1719
                              children [
                                HingeJoint {
                                  jointParameters HingeJointParameters {
                                    axis 0 0 1
                                  }
                                  device [
                                    RotationalMotor {
                                      name "elbow_joint"
                                      maxVelocity 3.15
                                      minPosition -3.14159265359
                                      maxPosition 3.14159265359
                                      maxTorque 150
                                    }
                                  ]
                                  endPoint Solid {
                                    children [
                                      UR10ForeArmShape {
                                      }
                                      Transform {
                                        translation 0 0.5723 0
                                        rotation 0 0 1 1.57079632679
                                        children [
                                          HingeJoint {
                                            jointParameters HingeJointParameters {
                                              axis 0 0 1
                                            }
                                            device [
                                              RotationalMotor {
                                                name "wrist_1_joint"
                                                maxVelocity 3.2
                                                minPosition -3.14159265359
                                                maxPosition 3.14159265359
                                                maxTorque 54
                                              }
                                            ]
                                            endPoint Solid {
                                              children [
                                                UR10Wrist1Shape {
                                                }
                                                Transform {
                                                  translation 0 0 0.1149
                                                  children [
                                                    HingeJoint {
                                                      jointParameters HingeJointParameters {
                                                        axis 0 1 0
                                                      }
                                                      device [
                                                        RotationalMotor {
                                                          name "wrist_2_joint"
                                                          maxVelocity 3.2
                                                          minPosition -3.14159265359
                                                          maxPosition 3.14159265359
                                                          maxTorque 54
                                                        }
                                                      ]
                                                      endPoint Solid {
                                                        rotation 0 1 0 0
                                                        children [
                                                          UR10Wrist2Shape {
                                                          }
                                                          Transform {
                                                            translation 0 0.1157 0
                                                            children [
                                                              HingeJoint {
                                                                jointParameters HingeJointParameters {
                                                                  axis 0 0 1
                                                                }
                                                                device [
                                                                  RotationalMotor {
                                                                    name "wrist_3_joint"
                                                                    maxVelocity 3.2
                                                                    minPosition -3.14159265359
                                                                    maxPosition 3.14159265359
                                                                    maxTorque 54
                                                                  }
                                                                ]
                                                                endPoint Solid {
                                                                  children [
                                                                    UR10Wrist3Shape {
                                                                    }
                                                                    GPS {
                                                                      translation 0 0 0.0922
                                                                    }
                                                                    Transform {
                                                                      translation 0 0 1.1
                                                                      rotation 0 1 0 -3.141592653589793
                                                                      children [
                                                                        DEF INITIAL_BALL_JOINT BallJoint {
                                                                          jointParameters BallJointParameters {
                                                                            anchor 0 0 0.99
                                                                          }
                                                                          endPoint DEF ROPE_INITIAL_ELEMENT Solid {
                                                                            translation 0 0 0.99
                                                                            rotation 0 1 0 0
                                                                            children [
                                                                              DEF BALL_JOINT_1 BallJoint {
                                                                                jointParameters BallJointParameters {
                                                                                  springConstant 1
                                                                                }
                                                                                endPoint DEF ROPE_ELEMENT_1 Solid {
                                                                                  translation 0 0 -0.1
                                                                                  rotation 0 1 0 0
                                                                                  children [
                                                                                    DEF ROPE_ELEMENT Transform {
                                                                                      translation 0 0 0.05
                                                                                      children [
                                                                                        Shape {
                                                                                          appearance PBRAppearance {
                                                                                            baseColor 0.8 0.8 0.8
                                                                                            roughness 1
                                                                                            metalness 0
                                                                                          }
                                                                                          geometry Capsule {
                                                                                            height 0.1
                                                                                            radius 0.005
                                                                                          }
                                                                                        }
                                                                                      ]
                                                                                    }
                                                                                    DEF BALL_JOINT_2 BallJoint {
                                                                                      jointParameters BallJointParameters {
                                                                                        springConstant 1
                                                                                      }
                                                                                      endPoint DEF ROPE_ELEMENT_2 Solid {
                                                                                        translation 0 0 -0.1
                                                                                        rotation 0 1 0 0
                                                                                        children [
                                                                                          USE ROPE_ELEMENT
                                                                                          DEF BALL_JOINT_3 BallJoint {
                                                                                            jointParameters BallJointParameters {
                                                                                              springConstant 1
                                                                                            }
                                                                                            endPoint DEF ROPE_ELEMENT_3 Solid {
                                                                                              translation 0 0 -0.1
                                                                                              rotation 0 1 0 0
                                                                                              children [
                                                                                                USE ROPE_ELEMENT
                                                                                                DEF BALL_JOINT_4 BallJoint {
                                                                                                  jointParameters BallJointParameters {
                                                                                                    springConstant 1
                                                                                                  }
                                                                                                  endPoint DEF ROPE_ELEMENT_4 Solid {
                                                                                                    translation 0 0 -0.1
                                                                                                    rotation 0 1 0 0
                                                                                                    children [
                                                                                                      USE ROPE_ELEMENT
                                                                                                      DEF BALL_JOINT_5 BallJoint {
                                                                                                        jointParameters BallJointParameters {
                                                                                                          springConstant 1
                                                                                                        }
                                                                                                        endPoint DEF ROPE_ELEMENT_5 Solid {
                                                                                                          translation 0 0 -0.1
                                                                                                          rotation 0 1 0 0
                                                                                                          children [
                                                                                                            USE ROPE_ELEMENT
                                                                                                            Solid {
                                                                                                              translation 0 0 -0.05
                                                                                                              children [
                                                                                                                DEF ROPE_MASS_SHAPE Shape {
                                                                                                                  appearance DEF SUPPORT_APPEARANCE PBRAppearance {
                                                                                                                    baseColor 0.564706 0.933333 0.564706
                                                                                                                    roughness 1
                                                                                                                    metalness 0
                                                                                                                  }
                                                                                                                  geometry Sphere {
                                                                                                                    radius 0.05
                                                                                                                    subdivision 2
                                                                                                                  }
                                                                                                                }
                                                                                                              ]
                                                                                                              boundingObject USE ROPE_MASS_SHAPE
                                                                                                              physics Physics {
                                                                                                              }
                                                                                                            }
                                                                                                          ]
                                                                                                          boundingObject USE ROPE_ELEMENT
                                                                                                          physics DEF ROPE_ELEMENT_PHYSICS Physics {
                                                                                                            density -1
                                                                                                            mass 0.0085
                                                                                                            centerOfMass [
                                                                                                              0 0 0
                                                                                                            ]
                                                                                                            inertiaMatrix [
                                                                                                              5.7e-05 5.7e-05 9.5e-06
                                                                                                              0 0 0
                                                                                                            ]
                                                                                                            damping Damping {
                                                                                                              linear 0.715292
                                                                                                              angular 0.715292
                                                                                                            }
                                                                                                          }
                                                                                                        }
                                                                                                      }
                                                                                                    ]
                                                                                                    boundingObject USE ROPE_ELEMENT
                                                                                                    physics USE ROPE_ELEMENT_PHYSICS
                                                                                                  }
                                                                                                }
                                                                                              ]
                                                                                              boundingObject USE ROPE_ELEMENT
                                                                                              physics USE ROPE_ELEMENT_PHYSICS
                                                                                            }
                                                                                          }
                                                                                        ]
                                                                                        boundingObject USE ROPE_ELEMENT
                                                                                        physics USE ROPE_ELEMENT_PHYSICS
                                                                                      }
                                                                                    }
                                                                                  ]
                                                                                  boundingObject USE ROPE_ELEMENT
                                                                                  physics USE ROPE_ELEMENT_PHYSICS
                                                                                }
                                                                              }
                                                                            ]
                                                                            boundingObject Sphere {
                                                                              radius 0.005
                                                                            }
                                                                            physics USE ROPE_ELEMENT_PHYSICS
                                                                          }
                                                                        }
                                                                      ]
                                                                    }
                                                                  ]
                                                                  name "ur10_wrist_3"
                                                                  boundingObject UR10Wrist3Collision {
                                                                  }
                                                                  physics Physics {
                                                                    density -1
                                                                    mass 0.202
                                                                    centerOfMass [
                                                                      0 0 0
                                                                    ]
                                                                    inertiaMatrix [
                                                                      0.0005264625 0.0005264625 9.46875e-05
                                                                      0 0 0
                                                                    ]
                                                                  }
                                                                }
                                                              }
                                                            ]
                                                          }
                                                        ]
                                                        name "ur10_wrist_2"
                                                        boundingObject UR10Wrist2Collision {
                                                        }
                                                        physics Physics {
                                                          density -1
                                                          mass 1.96
                                                          centerOfMass [
                                                            0 0 0
                                                          ]
                                                          inertiaMatrix [
                                                            0.00510825 0.00510825 0.00091875
                                                            0 0 0
                                                          ]
                                                        }
                                                      }
                                                    }
                                                  ]
                                                }
                                              ]
                                              name "ur10_wrist_1"
                                              boundingObject UR10Wrist1Collision {
                                              }
                                              physics Physics {
                                                density -1
                                                mass 1.96
                                                centerOfMass [
                                                  0 0 0
                                                ]
                                                inertiaMatrix [
                                                  0.00510825 0.00510825 0.00091875
                                                  0 0 0
                                                ]
                                              }
                                            }
                                          }
                                        ]
                                      }
                                    ]
                                    name "ur10_forearm"
                                    boundingObject UR10ForeArmCollision {
                                    }
                                    physics Physics {
                                      density -1
                                      mass 3.87
                                      centerOfMass [
                                        0 0.28615 0
                                      ]
                                      inertiaMatrix [
                                        0.111069738525 0.111069738525 0.0018140625
                                        0 0 0
                                      ]
                                    }
                                  }
                                }
                              ]
                            }
                          ]
                          name "ur10_upper_arm"
                          boundingObject UR10UpperArmCollision {
                          }
                          physics Physics {
                            density -1
                            mass 12.93
                            centerOfMass [
                              0 0.306 0
                            ]
                            inertiaMatrix [
                              0.4217539725 0.4217539725 0.0060609375
                              0 0 0
                            ]
                          }
                        }
                      }
                    ]
                  }
                ]
                name "ur10_shoulder"
                boundingObject UR10ShoulderCollision {
                }
                physics Physics {
                  density -1
                  mass 7.778
                  centerOfMass [
                    0 0 0
                  ]
                  inertiaMatrix [
                    0.031474325166667 0.031474325166667 0.0036459375
                    0 0 0
                  ]
                }
              }
            }
          ]
        }
      ]
      name "ur10"
      boundingObject UR10BaseCollision {
      }
      physics Physics {
        density -1
        mass 4
        centerOfMass [
          0 0 0
        ]
        inertiaMatrix [
          0.0061063333333333 0.0061063333333333 0.001875
          0 0 0
        ]
      }
    }
  ]
  name "UR10"
  controller ""
  controllerArgs [
    ""
  ]
}
Robot {
  translation 0 0 1.3
  rotation 0 1 0 0
  children [
    Solid {
      rotation 1 0 0 1.57079632679
      children [
        UR10BaseShape {
        }
        Transform {
          translation 0 0.1273 0
          children [
            HingeJoint {
              jointParameters HingeJointParameters {
                axis 0 1 0
              }
              device [
                RotationalMotor {
                  name "shoulder_pan_joint"
                  maxVelocity 2.16
                  minPosition -3.14159265359
                  maxPosition 3.14159265359
                  maxTorque 330
                }
              ]
              endPoint Solid {
                rotation 0 1 0 0
                children [
                  UR10ShoulderShape {
                  }
                  Transform {
                    translation 0 0 0.220941
                    rotation 0 0 1 1.57079632679
                    children [
                      HingeJoint {
                        jointParameters HingeJointParameters {
                          axis 0 0 1
                        }
                        device [
                          RotationalMotor {
                            name "shoulder_lift_joint"
                            maxVelocity 2.16
                            minPosition -3.14159265359
                            maxPosition 3.14159265359
                            maxTorque 330
                          }
                        ]
                        endPoint Solid {
                          children [
                            UR10UpperArmShape {
                            }
                            Transform {
                              translation 0 0.612 -0.1719
                              children [
                                HingeJoint {
                                  jointParameters HingeJointParameters {
                                    axis 0 0 1
                                  }
                                  device [
                                    RotationalMotor {
                                      name "elbow_joint"
                                      maxVelocity 3.15
                                      minPosition -3.14159265359
                                      maxPosition 3.14159265359
                                      maxTorque 150
                                    }
                                  ]
                                  endPoint Solid {
                                    children [
                                      UR10ForeArmShape {
                                      }
                                      Transform {
                                        translation 0 0.5723 0
                                        rotation 0 0 1 1.57079632679
                                        children [
                                          HingeJoint {
                                            jointParameters HingeJointParameters {
                                              axis 0 0 1
                                            }
                                            device [
                                              RotationalMotor {
                                                name "wrist_1_joint"
                                                maxVelocity 3.2
                                                minPosition -3.14159265359
                                                maxPosition 3.14159265359
                                                maxTorque 54
                                              }
                                            ]
                                            endPoint Solid {
                                              children [
                                                UR10Wrist1Shape {
                                                }
                                                Transform {
                                                  translation 0 0 0.1149
                                                  children [
                                                    HingeJoint {
                                                      jointParameters HingeJointParameters {
                                                        axis 0 1 0
                                                      }
                                                      device [
                                                        RotationalMotor {
                                                          name "wrist_2_joint"
                                                          maxVelocity 3.2
                                                          minPosition -3.14159265359
                                                          maxPosition 3.14159265359
                                                          maxTorque 54
                                                        }
                                                      ]
                                                      endPoint Solid {
                                                        rotation 0 1 0 0
                                                        children [
                                                          UR10Wrist2Shape {
                                                          }
                                                          Transform {
                                                            translation 0 0.1157 0
                                                            children [
                                                              HingeJoint {
                                                                jointParameters HingeJointParameters {
                                                                  axis 0 0 1
                                                                }
                                                                device [
                                                                  RotationalMotor {
                                                                    name "wrist_3_joint"
                                                                    maxVelocity 3.2
                                                                    minPosition -3.14159265359
                                                                    maxPosition 3.14159265359
                                                                    maxTorque 54
                                                                  }
                                                                ]
                                                                endPoint Solid {
                                                                  children [
                                                                    UR10Wrist3Shape {
                                                                    }
                                                                    GPS {
                                                                      translation 0 0 0.0922
                                                                    }
                                                                    Transform {
                                                                      translation 0 0 1.1
                                                                      rotation 0 1 0 -3.141592653589793
                                                                    }
                                                                  ]
                                                                  name "ur10_wrist_3"
                                                                  boundingObject UR10Wrist3Collision {
                                                                  }
                                                                  physics Physics {
                                                                    density -1
                                                                    mass 0.202
                                                                    centerOfMass [
                                                                      0 0 0
                                                                    ]
                                                                    inertiaMatrix [
                                                                      0.0005264625 0.0005264625 9.46875e-05
                                                                      0 0 0
                                                                    ]
                                                                  }
                                                                }
                                                              }
                                                            ]
                                                          }
                                                        ]
                                                        name "ur10_wrist_2"
                                                        boundingObject UR10Wrist2Collision {
                                                        }
                                                        physics Physics {
                                                          density -1
                                                          mass 1.96
                                                          centerOfMass [
                                                            0 0 0
                                                          ]
                                                          inertiaMatrix [
                                                            0.00510825 0.00510825 0.00091875
                                                            0 0 0
                                                          ]
                                                        }
                                                      }
                                                    }
                                                  ]
                                                }
                                              ]
                                              name "ur10_wrist_1"
                                              boundingObject UR10Wrist1Collision {
                                              }
                                              physics Physics {
                                                density -1
                                                mass 1.96
                                                centerOfMass [
                                                  0 0 0
                                                ]
                                                inertiaMatrix [
                                                  0.00510825 0.00510825 0.00091875
                                                  0 0 0
                                                ]
                                              }
                                            }
                                          }
                                        ]
                                      }
                                    ]
                                    name "ur10_forearm"
                                    boundingObject UR10ForeArmCollision {
                                    }
                                    physics Physics {
                                      density -1
                                      mass 3.87
                                      centerOfMass [
                                        0 0.28615 0
                                      ]
                                      inertiaMatrix [
                                        0.111069738525 0.111069738525 0.0018140625
                                        0 0 0
                                      ]
                                    }
                                  }
                                }
                              ]
                            }
                          ]
                          name "ur10_upper_arm"
                          boundingObject UR10UpperArmCollision {
                          }
                          physics Physics {
                            density -1
                            mass 12.93
                            centerOfMass [
                              0 0.306 0
                            ]
                            inertiaMatrix [
                              0.4217539725 0.4217539725 0.0060609375
                              0 0 0
                            ]
                          }
                        }
                      }
                    ]
                  }
                ]
                name "ur10_shoulder"
                boundingObject UR10ShoulderCollision {
                }
                physics Physics {
                  density -1
                  mass 7.778
                  centerOfMass [
                    0 0 0
                  ]
                  inertiaMatrix [
                    0.031474325166667 0.031474325166667 0.0036459375
                    0 0 0
                  ]
                }
              }
            }
          ]
        }
      ]
      name "ur10"
      boundingObject UR10BaseCollision {
      }
      physics Physics {
        density -1
        mass 4
        centerOfMass [
          0 0 0
        ]
        inertiaMatrix [
          0.0061063333333333 0.0061063333333333 0.001875
          0 0 0
        ]
      }
    }
  ]
  name "UR10(1)"
  controller "Controller_UR10"
}
