#VRML_SIM R2022a utf8
WorldInfo {
}
Viewpoint {
  orientation -0.23592877607924995 -0.18443360356470387 0.9541078861920621 4.563628438632753
  position -0.20599282811328334 4.385932132229726 2.826068114973717
}
TexturedBackground {
}
TexturedBackgroundLight {
}
RectangleArena {
  floorSize 15 50
}
UR10 {
  rotation 1 0 0 1.5707996938995747
}
Robot {
  translation -0.5 0 0
  rotation 0 1 0 0
  children [
    Solid {
      rotation 1 0 0 1.57079632679
      children [
        UR10BaseShape {
        }
        Transform {
          translation 0 0.1273 0
          children [
            HingeJoint {
              jointParameters HingeJointParameters {
                axis 0 1 0
              }
              device [
                RotationalMotor {
                  name "shoulder_pan_joint"
                  maxVelocity 2.16
                  minPosition -3.14159265359
                  maxPosition 3.14159265359
                  maxTorque 330
                }
              ]
              endPoint Solid {
                rotation 0 1 0 0
                children [
                  UR10ShoulderShape {
                  }
                  Transform {
                    translation 0 0 0.220941
                    rotation 0 0 1 1.57079632679
                    children [
                      HingeJoint {
                        jointParameters HingeJointParameters {
                          axis 0 0 1
                        }
                        device [
                          RotationalMotor {
                            name "shoulder_lift_joint"
                            maxVelocity 2.16
                            minPosition -3.14159265359
                            maxPosition 3.14159265359
                            maxTorque 330
                          }
                        ]
                        endPoint Solid {
                          children [
                            UR10UpperArmShape {
                            }
                            Transform {
                              translation 0 0.612 -0.1719
                              children [
                                HingeJoint {
                                  jointParameters HingeJointParameters {
                                    axis 0 0 1
                                  }
                                  device [
                                    RotationalMotor {
                                      name "elbow_joint"
                                      maxVelocity 3.15
                                      minPosition -3.14159265359
                                      maxPosition 3.14159265359
                                      maxTorque 150
                                    }
                                  ]
                                  endPoint Solid {
                                    children [
                                      UR10ForeArmShape {
                                      }
                                      Transform {
                                        translation 0 0.5723 0
                                        rotation 0 0 1 1.57079632679
                                        children [
                                          HingeJoint {
                                            jointParameters HingeJointParameters {
                                              axis 0 0 1
                                            }
                                            device [
                                              RotationalMotor {
                                                name "wrist_1_joint"
                                                maxVelocity 3.2
                                                minPosition -3.14159265359
                                                maxPosition 3.14159265359
                                                maxTorque 54
                                              }
                                            ]
                                            endPoint Solid {
                                              children [
                                                UR10Wrist1Shape {
                                                }
                                                Transform {
                                                  translation 0 0 0.1149
                                                  children [
                                                    HingeJoint {
                                                      jointParameters HingeJointParameters {
                                                        axis 0 1 0
                                                      }
                                                      device [
                                                        RotationalMotor {
                                                          name "wrist_2_joint"
                                                          maxVelocity 3.2
                                                          minPosition -3.14159265359
                                                          maxPosition 3.14159265359
                                                          maxTorque 54
                                                        }
                                                      ]
                                                      endPoint Solid {
                                                        rotation 0 1 0 0
                                                        children [
                                                          UR10Wrist2Shape {
                                                          }
                                                          Transform {
                                                            translation 0 0.1157 0
                                                            children [
                                                              HingeJoint {
                                                                jointParameters HingeJointParameters {
                                                                  axis 0 0 1
                                                                }
                                                                device [
                                                                  RotationalMotor {
                                                                    name "wrist_3_joint"
                                                                    maxVelocity 3.2
                                                                    minPosition -3.14159265359
                                                                    maxPosition 3.14159265359
                                                                    maxTorque 54
                                                                  }
                                                                ]
                                                                endPoint Solid {
                                                                  children [
                                                                    UR10Wrist3Shape {
                                                                    }
                                                                    GPS {
                                                                      translation 0 0 0.0922
                                                                    }
                                                                    Transform {
                                                                      translation 0 0 1.1
                                                                      rotation 0 1 0 -3.141592653589793
                                                                    }
                                                                  ]
                                                                  name "ur10_wrist_3"
                                                                  boundingObject UR10Wrist3Collision {
                                                                  }
                                                                  physics Physics {
                                                                    density -1
                                                                    mass 0.202
                                                                    centerOfMass [
                                                                      0 0 0
                                                                    ]
                                                                    inertiaMatrix [
                                                                      0.0005264625 0.0005264625 9.46875e-05
                                                                      0 0 0
                                                                    ]
                                                                  }
                                                                }
                                                              }
                                                            ]
                                                          }
                                                        ]
                                                        name "ur10_wrist_2"
                                                        boundingObject UR10Wrist2Collision {
                                                        }
                                                        physics Physics {
                                                          density -1
                                                          mass 1.96
                                                          centerOfMass [
                                                            0 0 0
                                                          ]
                                                          inertiaMatrix [
                                                            0.00510825 0.00510825 0.00091875
                                                            0 0 0
                                                          ]
                                                        }
                                                      }
                                                    }
                                                  ]
                                                }
                                              ]
                                              name "ur10_wrist_1"
                                              boundingObject UR10Wrist1Collision {
                                              }
                                              physics Physics {
                                                density -1
                                                mass 1.96
                                                centerOfMass [
                                                  0 0 0
                                                ]
                                                inertiaMatrix [
                                                  0.00510825 0.00510825 0.00091875
                                                  0 0 0
                                                ]
                                              }
                                            }
                                          }
                                        ]
                                      }
                                    ]
                                    name "ur10_forearm"
                                    boundingObject UR10ForeArmCollision {
                                    }
                                    physics Physics {
                                      density -1
                                      mass 3.87
                                      centerOfMass [
                                        0 0.28615 0
                                      ]
                                      inertiaMatrix [
                                        0.111069738525 0.111069738525 0.0018140625
                                        0 0 0
                                      ]
                                    }
                                  }
                                }
                              ]
                            }
                          ]
                          name "ur10_upper_arm"
                          boundingObject UR10UpperArmCollision {
                          }
                          physics Physics {
                            density -1
                            mass 12.93
                            centerOfMass [
                              0 0.306 0
                            ]
                            inertiaMatrix [
                              0.4217539725 0.4217539725 0.0060609375
                              0 0 0
                            ]
                          }
                        }
                      }
                    ]
                  }
                ]
                name "ur10_shoulder"
                boundingObject UR10ShoulderCollision {
                }
                physics Physics {
                  density -1
                  mass 7.778
                  centerOfMass [
                    0 0 0
                  ]
                  inertiaMatrix [
                    0.031474325166667 0.031474325166667 0.0036459375
                    0 0 0
                  ]
                }
              }
            }
          ]
        }
      ]
      name "ur10"
      boundingObject UR10BaseCollision {
      }
      physics Physics {
        density -1
        mass 4
        centerOfMass [
          0 0 0
        ]
        inertiaMatrix [
          0.0061063333333333 0.0061063333333333 0.001875
          0 0 0
        ]
      }
    }
  ]
  name "UR10"
  controller "Controller_UR10"
}
